Workbook

Sheet Time Sheet
H1: Weekly Time Sheet
F3: Complete Control Solutions, Inc. | L3: Name: | M3: CHRISTOPHER PANICI
F4: 3701 E. Evergreen Dr. Suite 400 | M4: W5531 AMY AVE
F5: Appleton, WI 54913 | M5: APPLETON, WI 54915
E7: Week of | F7: 46026 | I7: to | J7: =F7+6 -> 46032
A11: Work Codes: | D11: 2200 | E11: Technician Labor - Shop
A12: 1000 | B12: Office | D12: 2400 | E12: Technician Labor - Field | K12: Overtime - Saturdays & Over 8 hours/day
A13: 1200 | B13: Vacation | D13: 4000 | E13: Testing
A14: 1300 | B14: Sick / Personal Time | D14: 4200 | E14: PLC Programming
A15: 1400 | B15: Sales/Marketing & R/D | D15: 4400 | E15: HMI/SCADA Programming | K15: Double Time - Required work on Sundays
A16: 1500 | B16: Warranty Work | D16: 4700 | E16: Project Management
A17: 1600 | B17: Travel Time | D17: 4800 | E17: Electrical Design/Eng
A18: 1700 | B18: Training | D18: 4900 | E18: Drafting | K18: StartUp - "S" Designation after Job Number
A19: Date | B19: Job Number | C19: Work Code | D19: Reg. Time Hrs | E19: Overtime Hrs. | F19: Dbl Time Hrs. | G19: Description of Work | N19: Overnight Stay
N20: Overnight Travel Bonus
A21: =TEXT(A22,"dddd") -> Sunday
A22: =F7 -> 46026
A23: `
N24: =FALSE() -> FALSE | O24: =SUM(D20:F24) -> 0
N25: Overnight Travel Bonus
A26: =TEXT(A27,"dddd") -> Monday
A27: =A22+1 -> 46027
N29: =FALSE() -> FALSE | O29: =SUM(D25:F29) -> 0
N30: Overnight Travel Bonus
A31: =TEXT(A32,"dddd") -> Tuesday
A32: =A27+1 -> 46028
N34: =FALSE() -> FALSE | O34: =SUM(D30:F34) -> 0
N35: Overnight Travel Bonus
A36: =TEXT(A37,"dddd") -> Wednesday
A37: =A32+1 -> 46029
N39: =FALSE() -> FALSE | O39: =SUM(D35:F39) -> 0
N40: Overnight Travel Bonus
A41: =TEXT(A42,"dddd") -> Thursday
A42: =A37+1 -> 46030
N44: =FALSE() -> FALSE | O44: =SUM(D40:F44) -> 0
N45: Overnight Travel Bonus
A46: =TEXT(A47,"dddd") -> Friday
A47: =A42+1 -> 46031
N49: =FALSE() -> FALSE | O49: =SUM(D45:F49) -> 0
N50: Overnight Travel Bonus
...

Sheet Expense Report
C1: Per Diem Food | F1: ='Time Sheet'!F3:J3 -> Complete Control Solutions, Inc. | L1: WEEKLY EXPENSE REPORT
C2: Travel Days $37.50 | F2: ='Time Sheet'!F4:J4 -> 3701 E. Evergreen Dr. Suite 400
C3: Overnight Stays $50 | F3: ='Time Sheet'!F5:J5 -> Appleton, WI 54913 | L3: Name: | M3: ='Time Sheet'!M3 -> CHRISTOPHER PANICI
M4: ='Time Sheet'!M4 -> W5531 AMY AVE
F5: ='Time Sheet'!F7:H7 -> 46026 | H5: to | I5: =F5+6 -> 46032 | M5: ='Time Sheet'!M5 -> APPLETON, WI 54915
M6: ='Time Sheet'!M6
E7: Per Diem | F7: Air | H7: Tolls/ | I7: Rental | J7: Business | K7: Other | L7: Explanation of | N7: Daily
A8: Date | B8: Job # | C8: Miles | D8: Mileage | E8: Food | F8: Fare | G8: Hotel | H8: Parking | I8: Car/Fuel | J8: Meals | K8: Expense | L8: Expenses | N8: Total
A9: ='Time Sheet'!A21 -> Sunday | B9: =IF('Time Sheet'!B20<>0, 'Time Sheet'!B20,"") | D9: =C9*0.7 -> 0 | N9: =SUM(D9:K9) -> 0
A10: =F5 -> 46026 | B10: =IF('Time Sheet'!B21<>0,'Time Sheet'!B21,"") | D10: =C10*0.7 -> 0 | N10: =SUM(D10:K10) -> 0
B11: =IF('Time Sheet'!B22<>0,'Time Sheet'!B22,"") | D11: =C11*0.7 -> 0 | N11: =SUM(D11:K11) -> 0
B12: =IF('Time Sheet'!B23<>0,'Time Sheet'!B23,"") | D12: =C12*0.7 -> 0 | N12: =SUM(D12:K12) -> 0
B13: =IF('Time Sheet'!B24<>0,'Time Sheet'!B24,"") | D13: =C13*0.7 -> 0 | N13: =SUM(D13:K13) -> 0
A14: ='Time Sheet'!A26 -> Monday | B14: =IF('Time Sheet'!B25<>0,'Time Sheet'!B25,"") | D14: =C14*0.7 -> 0 | N14: =SUM(D14:K14) -> 0
A15: =A10+1 -> 46027 | B15: =IF('Time Sheet'!B26<>0,'Time Sheet'!B26,"") | D15: =C15*0.7 -> 0 | N15: =SUM(D15:K15) -> 0
B16: =IF('Time Sheet'!B27<>0,'Time Sheet'!B27,"") | D16: =C16*0.7 -> 0 | N16: =SUM(D16:K16) -> 0
B17: =IF('Time Sheet'!B28<>0,'Time Sheet'!B28,"") | D17: =C17*0.7 -> 0 | N17: =SUM(D17:K17) -> 0
B18: =IF('Time Sheet'!B29<>0,'Time Sheet'!B29,"") | D18: =C18*0.7 -> 0 | N18: =SUM(D18:K18) -> 0
A19: ='Time Sheet'!A31 -> Tuesday | B19: =IF('Time Sheet'!B30<>0,'Time Sheet'!B30,"") | D19: =C19*0.7 -> 0 | N19: =SUM(D19:K19) -> 0
A20: =A15+1 -> 46028 | B20: =IF('Time Sheet'!B31<>0,'Time Sheet'!B31,"") | D20: =C20*0.7 -> 0 | N20: =SUM(D20:K20) -> 0
B21: =IF('Time Sheet'!B32<>0,'Time Sheet'!B32,"") | D21: =C21*0.7 -> 0 | N21: =SUM(D21:K21) -> 0
B22: =IF('Time Sheet'!B33<>0,'Time Sheet'!B33,"") | D22: =C22*0.7 -> 0 | N22: =SUM(D22:K22) -> 0
B23: =IF('Time Sheet'!B34<>0,'Time Sheet'!B34,"") | D23: =C23*0.7 -> 0 | N23: =SUM(D23:K23) -> 0
A24: ='Time Sheet'!A36 -> Wednesday | B24: =IF('Time Sheet'!B35<>0,'Time Sheet'!B35,"") | D24: =C24*0.7 -> 0 | N24: =SUM(D24:K24) -> 0
A25: =A20+1 -> 46029 | B25: =IF('Time Sheet'!B36<>0,'Time Sheet'!B36,"") | D25: =C25*0.7 -> 0 | N25: =SUM(D25:K25) -> 0
B26: =IF('Time Sheet'!B37<>0,'Time Sheet'!B37,"") | D26: =C26*0.7 -> 0 | N26: =SUM(D26:K26) -> 0
B27: =IF('Time Sheet'!B38<>0,'Time Sheet'!B38,"") | D27: =C27*0.7 -> 0 | N27: =SUM(D27:K27) -> 0
B28: =IF('Time Sheet'!B39<>0,'Time Sheet'!B39,"") | D28: =C28*0.7 -> 0 | N28: =SUM(D28:K28) -> 0
A29: ='Time Sheet'!A41 -> Thursday | B29: =IF('Time Sheet'!B40<>0,'Time Sheet'!B40,"") | D29: =C29*0.7 -> 0 | N29: =SUM(D29:K29) -> 0
A30: =A25+1 -> 46030 | B30: =IF('Time Sheet'!B41<>0,'Time Sheet'!B41,"") | D30: =C30*0.7 -> 0 | N30: =SUM(D30:K30) -> 0
B31: =IF('Time Sheet'!B42<>0,'Time Sheet'!B42,"") | D31: =C31*0.7 -> 0 | N31: =SUM(D31:K31) -> 0
B32: =IF('Time Sheet'!B43<>0,'Time Sheet'!B43,"") | D32: =C32*0.7 -> 0 | N32: =SUM(D32:K32) -> 0
B33: =IF('Time Sheet'!B44<>0,'Time Sheet'!B44,"") | D33: =C33*0.7 -> 0 | N33: =SUM(D33:K33) -> 0
A34: ='Time Sheet'!A46 -> Friday | B34: =IF('Time Sheet'!B45<>0,'Time Sheet'!B45,"") | D34: =C34*0.7 -> 0 | N34: =SUM(D34:K34) -> 0
A35: =A30+1 -> 46031 | B35: =IF('Time Sheet'!B46<>0,'Time Sheet'!B46,"") | D35: =C35*0.7 -> 0 | N35: =SUM(D35:K35) -> 0
B36: =IF('Time Sheet'!B47<>0,'Time Sheet'!B47,"") | D36: =C36*0.7 -> 0 | N36: =SUM(D36:K36) -> 0
B37: =IF('Time Sheet'!B48<>0,'Time Sheet'!B48,"") | D37: =C37*0.7 -> 0 | N37: =SUM(D37:K37) -> 0
B38: =IF('Time Sheet'!B49<>0,'Time Sheet'!B49,"") | D38: =C38*0.7 -> 0 | N38: =SUM(D38:K38) -> 0
A39: ='Time Sheet'!A51 -> Saturday | B39: =IF('Time Sheet'!B50<>0,'Time Sheet'!B50,"") | D39: =C39*0.7 -> 0 | N39: =SUM(D39:K39) -> 0
A40: =A35+1 -> 46032 | B40: =IF('Time Sheet'!B51<>0,'Time Sheet'!B51,"") | D40: =C40*0.7 -> 0 | N40: =SUM(D40:K40) -> 0
...

Sheet Parts Report
D1: Complete Control Solutions, Inc.
D2: 915 Indianhead Drive
D3: Mosinee, WI 54455
E5: PARTS- CHARGE TO JOBS/REPLENISHMENT REPORT
B7: EE Stock/ | D7: Part Description/ | E7: Additional Notes | F7: Re-Order
A8: Date | B8: Job # | C8: Quantity | D8: Part Number | E8: For Customer | F8: Part - Yes/No
A9: ='Time Sheet'!A21 -> Sunday | B9: =IF('Time Sheet'!B20<>0, 'Time Sheet'!B20,"")
A10: ='Expense Report'!A10:A13 -> 46026 | B10: =IF('Time Sheet'!B21<>0,'Time Sheet'!B21,"")
B11: =IF('Time Sheet'!B22<>0,'Time Sheet'!B22,"")
B12: =IF('Time Sheet'!B23<>0,'Time Sheet'!B23,"")
B13: =IF('Time Sheet'!B24<>0,'Time Sheet'!B24,"")
B14: =IF('Time Sheet'!B25<>0,'Time Sheet'!B25,"")
A15: =A10+1 -> 46027 | B15: =IF('Time Sheet'!B26<>0,'Time Sheet'!B26,"")
B16: =IF('Time Sheet'!B27<>0,'Time Sheet'!B27,"")
B17: =IF('Time Sheet'!B28<>0,'Time Sheet'!B28,"")
B18: =IF('Time Sheet'!B29<>0,'Time Sheet'!B29,"")
A19: ='Time Sheet'!A31 -> Tuesday | B19: =IF('Time Sheet'!B30<>0,'Time Sheet'!B30,"")
A20: =A15+1 -> 46028 | B20: =IF('Time Sheet'!B31<>0,'Time Sheet'!B31,"")
B21: =IF('Time Sheet'!B32<>0,'Time Sheet'!B32,"")
B22: =IF('Time Sheet'!B33<>0,'Time Sheet'!B33,"")
B23: =IF('Time Sheet'!B34<>0,'Time Sheet'!B34,"")
A24: ='Time Sheet'!A36 -> Wednesday | B24: =IF('Time Sheet'!B35<>0,'Time Sheet'!B35,"")
A25: =A20+1 -> 46029 | B25: =IF('Time Sheet'!B36<>0,'Time Sheet'!B36,"")
B26: =IF('Time Sheet'!B37<>0,'Time Sheet'!B37,"")
B27: =IF('Time Sheet'!B38<>0,'Time Sheet'!B38,"")
B28: =IF('Time Sheet'!B39<>0,'Time Sheet'!B39,"")
A29: ='Time Sheet'!A41 -> Thursday | B29: =IF('Time Sheet'!B40<>0,'Time Sheet'!B40,"")
A30: =A25+1 -> 46030 | B30: =IF('Time Sheet'!B41<>0,'Time Sheet'!B41,"")
B31: =IF('Time Sheet'!B42<>0,'Time Sheet'!B42,"")
B32: =IF('Time Sheet'!B43<>0,'Time Sheet'!B43,"")
B33: =IF('Time Sheet'!B44<>0,'Time Sheet'!B44,"")
A34: ='Time Sheet'!A46 -> Friday | B34: =IF('Time Sheet'!B45<>0,'Time Sheet'!B45,"")
A35: =A30+1 -> 46031 | B35: =IF('Time Sheet'!B46<>0,'Time Sheet'!B46,"")
B36: =IF('Time Sheet'!B47<>0,'Time Sheet'!B47,"")
B37: =IF('Time Sheet'!B48<>0,'Time Sheet'!B48,"")
B38: =IF('Time Sheet'!B49<>0,'Time Sheet'!B49,"")
A39: ='Time Sheet'!A51 -> Saturday | B39: =IF('Time Sheet'!B50<>0,'Time Sheet'!B50,"")
A40: =A35+1 -> 46032 | B40: =IF('Time Sheet'!B51<>0,'Time Sheet'!B51,"")
B41: =IF('Time Sheet'!B52<>0,'Time Sheet'!B52,"")
B42: =IF('Time Sheet'!B53<>0,'Time Sheet'!B53,"")
...
